Workbook
Name TGR: DCF!$D$19
Name WACC: DCF!$D$18

Sheet Trading Comp
B2: Comp Table
C3: As of 8/27/2025
B4: Date | C4: =TODAY() -> 46037
B5: Currency | C5: USD
Z7: Trading Mulitples
D8: Current | E8: Share | F8: Enterprise | G8: Market | I8: Revenue | L8: EBITDA | N8: Net Income | Q8: Revenue Growth | S8: EBITDA Margin | U8: Profit Margin | X8: EV / Revenue | Z8: EV / EBITDA | AB8: P / E
B9: Ticker | C9: Company Name | D9: Price | E9: Count | F9: Value | G9: Cap | I9: 22 | J9: 23 | K9: 24 | L9: 23 | M9: 24 | N9: 23 | O9: 24 | Q9: 22-23 | R9: 23-24 | S9: 23 | T9: 24 | U9: 23 | V9: 24 | X9: 23 | Y9: 24 | Z9: 23 | AA9: 24 | AB9: 23 | AC9: 24
B11: LULU | C11: =_xlfn.XLOOKUP($B11,$B$36:$B$47,C$36:C$47,,0) -> Lululemon | D11: =_xlfn.XLOOKUP($B11,$B$36:$B$47,D$36:D$47,,0) -> 205.57 | E11: =_xlfn.XLOOKUP($B11,$B$36:$B$47,E$36:E$47,,0) -> 116.37023 | F11: =_xlfn.XLOOKUP($B11,$B$36:$B$47,F$36:F$47,,0) -> 24272.29 | G11: =_xlfn.XLOOKUP($B11,$B$36:$B$47,G$36:G$47,,0) -> 23059.22 | I11: =_xlfn.XLOOKUP($B11,$B$36:$B$47,I$36:I$47,,0) -> 8111 | J11: =_xlfn.XLOOKUP($B11,$B$36:$B$47,J$36:J$47,,0) -> 9619 | K11: =_xlfn.XLOOKUP($B11,$B$36:$B$47,K$36:K$47,,0) -> 10588 | L11: =_xlfn.XLOOKUP($B11,$B$36:$B$47,L$36:L$47,,0) -> 2587 | M11: =_xlfn.XLOOKUP($B11,$B$36:$B$47,M$36:M$47,,0) -> 2946 | N11: =_xlfn.XLOOKUP($B11,$B$36:$B$47,N$36:N$47,,0) -> 1550 | O11: =_xlfn.XLOOKUP($B11,$B$36:$B$47,O$36:O$47,,0) -> 1815 | Q11: =J11/I11-1 -> 0.18592036 | R11: =K11/J11-1 -> 0.10073812 | S11: =L11/J11 -> 0.26894688 | T11: =M11/K11 -> 0.27823952 | U11: =N11/J11 -> 0.16113941 | V11: =O11/K11 -> 0.17142048 | X11: =$F11/J11 -> 2.5233694 | Y11: =$F11/K11 -> 2.2924339 | Z11: =$F11/L11 -> 9.3824082 | AA11: =$F11/M11 -> 8.2390665 | AB11: =$F11/N11 -> 15.659542 | AC11: =$F11/O11 -> 13.373163
A13: 1 | B13: COLM | C13: =_xlfn.XLOOKUP($B13,$B$36:$B$47,C$36:C$47,,0) -> Columbia Sportswear | D13: =_xlfn.XLOOKUP($B13,$B$36:$B$47,D$36:D$47,,0) -> 55.18 | E13: =_xlfn.XLOOKUP($B13,$B$36:$B$47,E$36:E$47,,0) -> 58.5 | F13: =_xlfn.XLOOKUP($B13,$B$36:$B$47,F$36:F$47,,0) -> 3022.21 | G13: =_xlfn.XLOOKUP($B13,$B$36:$B$47,G$36:G$47,,0) -> 2502.31 | I13: =_xlfn.XLOOKUP($B13,$B$36:$B$47,I$36:I$47,,0) -> 3464 | J13: =_xlfn.XLOOKUP($B13,$B$36:$B$47,J$36:J$47,,0) -> 3487 | K13: =_xlfn.XLOOKUP($B13,$B$36:$B$47,K$36:K$47,,0) -> 3370 | L13: =_xlfn.XLOOKUP($B13,$B$36:$B$47,L$36:L$47,,0) -> 441 | M13: =_xlfn.XLOOKUP($B13,$B$36:$B$47,M$36:M$47,,0) -> 322 | N13: =_xlfn.XLOOKUP($B13,$B$36:$B$47,N$36:N$47,,0) -> 251 | O13: =_xlfn.XLOOKUP($B13,$B$36:$B$47,O$36:O$47,,0) -> 223 | Q13: =J13/I13-1 -> 0.0066397229 | R13: =K13/J13-1 -> -0.033553198 | S13: =L13/J13 -> 0.12646974 | T13: =M13/K13 -> 0.095548961 | U13: =N13/J13 -> 0.071981646 | V13: =O13/K13 -> 0.066172107 | X13: =$F13/J13 -> 0.86670777 | Y13: =$F13/K13 -> 0.89679822 | Z13: =$F13/L13 -> 6.8530839 | AA13: =$F13/M13 -> 9.3857453 | AB13: =$F13/N13 -> 12.040677 | AC13: =$F13/O13 -> 13.552511
A14: 2 | B14: UAA | C14: =_xlfn.XLOOKUP($B14,$B$36:$B$47,C$36:C$47,,0) -> Under Armour | D14: =_xlfn.XLOOKUP($B14,$B$36:$B$47,D$36:D$47,,0) -> 5.04 | E14: =_xlfn.XLOOKUP($B14,$B$36:$B$47,E$36:E$47,,0) -> 432.25 | F14: =_xlfn.XLOOKUP($B14,$B$36:$B$47,F$36:F$47,,0) -> 2142.76 | G14: =_xlfn.XLOOKUP($B14,$B$36:$B$47,G$36:G$47,,0) -> 2346.62 | I14: =_xlfn.XLOOKUP($B14,$B$36:$B$47,I$36:I$47,,0) -> 5859 | J14: =_xlfn.XLOOKUP($B14,$B$36:$B$47,J$36:J$47,,0) -> 5694 | K14: =_xlfn.XLOOKUP($B14,$B$36:$B$47,K$36:K$47,,0) -> 5166 | L14: =_xlfn.XLOOKUP($B14,$B$36:$B$47,L$36:L$47,,0) -> 375 | M14: =_xlfn.XLOOKUP($B14,$B$36:$B$47,M$36:M$47,,0) -> 307 | N14: =_xlfn.XLOOKUP($B14,$B$36:$B$47,N$36:N$47,,0) -> 232 | O14: =_xlfn.XLOOKUP($B14,$B$36:$B$47,O$36:O$47,,0) -> -201 | Q14: =J14/I14-1 -> -0.028161802 | R14: =K14/J14-1 -> -0.092729189 | S14: =L14/J14 -> 0.065858799 | T14: =M14/K14 -> 0.059427023 | U14: =N14/J14 -> 0.040744643 | V14: =O14/K14 -> -0.038908246 | X14: =$F14/J14 -> 0.37631893 | Y14: =$F14/K14 -> 0.41478126 | Z14: =$F14/L14 -> 5.7140267 | AA14: =$F14/M14 -> 6.9796743 | AB14: =$F14/N14 -> 9.2360345 | AC14: =$F14/O14 -> -10.660498
A15: 3 | B15: ATZAF | C15: =_xlfn.XLOOKUP($B15,$B$36:$B$47,C$36:C$47,,0) -> Artizia | D15: =_xlfn.XLOOKUP($B15,$B$36:$B$47,D$36:D$47,,0) -> 57.48 | E15: =_xlfn.XLOOKUP($B15,$B$36:$B$47,E$36:E$47,,0) -> 116.73 | F15: =_xlfn.XLOOKUP($B15,$B$36:$B$47,F$36:F$47,,0) -> 6579.19 | G15: =_xlfn.XLOOKUP($B15,$B$36:$B$47,G$36:G$47,,0) -> 6722.82 | I15: =_xlfn.XLOOKUP($B15,$B$36:$B$47,I$36:I$47,,0) -> 1670.9 | J15: =_xlfn.XLOOKUP($B15,$B$36:$B$47,J$36:J$47,,0) -> 1727.6 | K15: =_xlfn.XLOOKUP($B15,$B$36:$B$47,K$36:K$47,,0) -> 1977.8 | L15: =_xlfn.XLOOKUP($B15,$B$36:$B$47,L$36:L$47,,0) -> 241.8 | M15: =_xlfn.XLOOKUP($B15,$B$36:$B$47,M$36:M$47,,0) -> 347.8 | N15: =_xlfn.XLOOKUP($B15,$B$36:$B$47,N$36:N$47,,0) -> 58.4 | O15: =_xlfn.XLOOKUP($B15,$B$36:$B$47,O$36:O$47,,0) -> 150.1 | Q15: =J15/I15-1 -> 0.033933808 | R15: =K15/J15-1 -> 0.14482519 | S15: =L15/J15 -> 0.13996295 | T15: =M15/K15 -> 0.17585196 | U15: =N15/J15 -> 0.033804121 | V15: =O15/K15 -> 0.075892406 | X15: =$F15/J15 -> 3.8082832 | Y15: =$F15/K15 -> 3.3265194 | Z15: =$F15/L15 -> 27.209222 | AA15: =$F15/M15 -> 18.91659 | AB15: =$F15/N15 -> 112.65736 | AC15: =$F15/O15 -> 43.832045
A16: 4 | B16: NIKE | C16: =_xlfn.XLOOKUP($B16,$B$36:$B$47,C$36:C$47,,0) -> Nike | D16: =_xlfn.XLOOKUP($B16,$B$36:$B$47,D$36:D$47,,0) -> 78.06 | E16: =_xlfn.XLOOKUP($B16,$B$36:$B$47,E$36:E$47,,0) -> 1487.6 | F16: =_xlfn.XLOOKUP($B16,$B$36:$B$47,F$36:F$47,,0) -> 115287.09 | G16: =_xlfn.XLOOKUP($B16,$B$36:$B$47,G$36:G$47,,0) -> 114937.33 | I16: =_xlfn.XLOOKUP($B16,$B$36:$B$47,I$36:I$47,,0) -> 46792 | J16: =_xlfn.XLOOKUP($B16,$B$36:$B$47,J$36:J$47,,0) -> 51191 | K16: =_xlfn.XLOOKUP($B16,$B$36:$B$47,K$36:K$47,,0) -> 51386 | L16: =_xlfn.XLOOKUP($B16,$B$36:$B$47,L$36:L$47,,0) -> 6016 | M16: =_xlfn.XLOOKUP($B16,$B$36:$B$47,M$36:M$47,,0) -> 6839 | N16: =_xlfn.XLOOKUP($B16,$B$36:$B$47,N$36:N$47,,0) -> 5070 | O16: =_xlfn.XLOOKUP($B16,$B$36:$B$47,O$36:O$47,,0) -> 5700 | Q16: =J16/I16-1 -> 0.094011797 | R16: =K16/J16-1 -> 0.0038092633 | S16: =L16/J16 -> 0.11752066 | T16: =M16/K16 -> 0.13309073 | U16: =N16/J16 -> 0.099040847 | V16: =O16/K16 -> 0.11092515 | X16: =$F16/J16 -> 2.2520969 | Y16: =$F16/K16 -> 2.2435506 | Z16: =$F16/L16 -> 19.163413 | AA16: =$F16/M16 -> 16.857302 | AB16: =$F16/N16 -> 22.739071 | AC16: =$F16/O16 -> 20.225805
A17: 5 | B17: ADDDF | C17: =_xlfn.XLOOKUP($B17,$B$36:$B$47,C$36:C$47,,0) -> Adidas | D17: =_xlfn.XLOOKUP($B17,$B$36:$B$47,D$36:D$47,,0) -> 194.69 | E17: =_xlfn.XLOOKUP($B17,$B$36:$B$47,E$36:E$47,,0) -> 178.56 | F17: =_xlfn.XLOOKUP($B17,$B$36:$B$47,F$36:F$47,,0) -> 34895.2 | G17: =_xlfn.XLOOKUP($B17,$B$36:$B$47,G$36:G$47,,0) -> 37627.2 | I17: =_xlfn.XLOOKUP($B17,$B$36:$B$47,I$36:I$47,,0) -> 23658 | J17: =_xlfn.XLOOKUP($B17,$B$36:$B$47,J$36:J$47,,0) -> 23165 | K17: =_xlfn.XLOOKUP($B17,$B$36:$B$47,K$36:K$47,,0) -> 25618 | L17: =_xlfn.XLOOKUP($B17,$B$36:$B$47,L$36:L$47,,0) -> 1463 | M17: =_xlfn.XLOOKUP($B17,$B$36:$B$47,M$36:M$47,,0) -> 2618 | N17: =_xlfn.XLOOKUP($B17,$B$36:$B$47,N$36:N$47,,0) -> -129 | O17: =_xlfn.XLOOKUP($B17,$B$36:$B$47,O$36:O$47,,0) -> 818 | Q17: =J17/I17-1 -> -0.020838617 | R17: =K17/J17-1 -> 0.10589251 | S17: =L17/J17 -> 0.063155623 | T17: =M17/K17 -> 0.10219377 | U17: =N17/J17 -> -0.005568746 | V17: =O17/K17 -> 0.031930674 | X17: =$F17/J17 -> 1.506376 | Y17: =$F17/K17 -> 1.362136 | Z17: =$F17/L17 -> 23.851811 | AA17: =$F17/M17 -> 13.328953 | AB17: =$F17/N17 -> -270.50543 | AC17: =$F17/O17 -> 42.659169
A18: 6 | B18: RL | C18: =_xlfn.XLOOKUP($B18,$B$36:$B$47,C$36:C$47,,0) -> Ralph Lauren Corporation | D18: =_xlfn.XLOOKUP($B18,$B$36:$B$47,D$36:D$47,,0) -> 294.64 | E18: =_xlfn.XLOOKUP($B18,$B$36:$B$47,E$36:E$47,,0) -> 64 | F18: =_xlfn.XLOOKUP($B18,$B$36:$B$47,F$36:F$47,,0) -> 17765.87 | G18: =_xlfn.XLOOKUP($B18,$B$36:$B$47,G$36:G$47,,0) -> 17498.34 | I18: =_xlfn.XLOOKUP($B18,$B$36:$B$47,I$36:I$47,,0) -> 6219 | J18: =_xlfn.XLOOKUP($B18,$B$36:$B$47,J$36:J$47,,0) -> 6444 | K18: =_xlfn.XLOOKUP($B18,$B$36:$B$47,K$36:K$47,,0) -> 6631 | L18: =_xlfn.XLOOKUP($B18,$B$36:$B$47,L$36:L$47,,0) -> 967 | M18: =_xlfn.XLOOKUP($B18,$B$36:$B$47,M$36:M$47,,0) -> 1045 | N18: =_xlfn.XLOOKUP($B18,$B$36:$B$47,N$36:N$47,,0) -> 523 | O18: =_xlfn.XLOOKUP($B18,$B$36:$B$47,O$36:O$47,,0) -> 646 | Q18: =J18/I18-1 -> 0.03617945 | R18: =K18/J18-1 -> 0.029019243 | S18: =L18/J18 -> 0.15006207 | T18: =M18/K18 -> 0.15759312 | U18: =N18/J18 -> 0.08116077 | V18: =O18/K18 -> 0.097421203 | X18: =$F18/J18 -> 2.7569631 | Y18: =$F18/K18 -> 2.6792143 | Z18: =$F18/L18 -> 18.372151 | AA18: =$F18/M18 -> 17.000833 | AB18: =$F18/N18 -> 33.969159 | AC18: =$F18/O18 -> 27.501347
A19: 7 | B19: DKS | C19: =_xlfn.XLOOKUP($B19,$B$36:$B$47,C$36:C$47,,0) -> Dick's Sporting Goods | D19: =_xlfn.XLOOKUP($B19,$B$36:$B$47,D$36:D$47,,0) -> 226.01 | E19: =_xlfn.XLOOKUP($B19,$B$36:$B$47,E$36:E$47,,0) -> 82.93 | F19: =_xlfn.XLOOKUP($B19,$B$36:$B$47,F$36:F$47,,0) -> 18165.96 | G19: =_xlfn.XLOOKUP($B19,$B$36:$B$47,G$36:G$47,,0) -> 19070.8 | I19: =_xlfn.XLOOKUP($B19,$B$36:$B$47,I$36:I$47,,0) -> 12368 | J19: =_xlfn.XLOOKUP($B19,$B$36:$B$47,J$36:J$47,,0) -> 12984 | K19: =_xlfn.XLOOKUP($B19,$B$36:$B$47,K$36:K$47,,0) -> 13443 | L19: =_xlfn.XLOOKUP($B19,$B$36:$B$47,L$36:L$47,,0) -> 1770 | M19: =_xlfn.XLOOKUP($B19,$B$36:$B$47,M$36:M$47,,0) -> 1929 | N19: =_xlfn.XLOOKUP($B19,$B$36:$B$47,N$36:N$47,,0) -> 1047 | O19: =_xlfn.XLOOKUP($B19,$B$36:$B$47,O$36:O$47,,0) -> 1165 | Q19: =J19/I19-1 -> 0.049805951 | R19: =K19/J19-1 -> 0.035351201 | S19: =L19/J19 -> 0.13632163 | T19: =M19/K19 -> 0.14349476 | U19: =N19/J19 -> 0.080637708 | V19: =O19/K19 -> 0.086662203 | X19: =$F19/J19 -> 1.3991035 | Y19: =$F19/K19 -> 1.3513323 | Z19: =$F19/L19 -> 10.263254 | AA19: =$F19/M19 -> 9.4172939 | AB19: =$F19/N19 -> 17.350487 | AC19: =$F19/O19 -> 15.593099
B21: Mean | Q21: =AVERAGE(Q11:Q19) -> 0.044686333 | R21: =AVERAGE(R11:R19) -> 0.036669143 | S21: =AVERAGE(S11:S19) -> 0.13353729 | T21: =AVERAGE(T11:T19) -> 0.14317998 | U21: =AVERAGE(U11:U19) -> 0.07036755 | V21: =AVERAGE(V11:V19) -> 0.075189497 | X21: =AVERAGE(X11:X19) -> 1.9361523 | Y21: =AVERAGE(Y11:Y19) -> 1.8208457 | Z21: =AVERAGE(Z11:Z19) -> 15.101171 | AA21: =AVERAGE(AA11:AA19) -> 12.515682 | AB21: =AVERAGE(AB11:AB19) -> -5.8566366 | AC21: =AVERAGE(AC11:AC19) -> 20.75958
B22: Median | Q22: =MEDIAN(Q11:Q19) -> 0.035056629 | R22: =MEDIAN(R11:R19) -> 0.032185222 | S22: =MEDIAN(S11:S19) -> 0.13139569 | T22: =MEDIAN(T11:T19) -> 0.13829274 | U22: =MEDIAN(U11:U19) -> 0.076309677 | V22: =MEDIAN(V11:V19) -> 0.081277305 | X22: =MEDIAN(X11:X19) -> 1.8792364 | Y22: =MEDIAN(Y11:Y19) -> 1.8028433 | Z22: =MEDIAN(Z11:Z19) -> 14.317703 | AA22: =MEDIAN(AA11:AA19) -> 11.373124 | AB22: =MEDIAN(AB11:AB19) -> 16.505015 | AC22: =MEDIAN(AC11:AC19) -> 17.909452
D24: 2024 Trading Multiple | H24: 2024 Financial Metric | L24: Enterprise Value | Q24: 2024 | T24: Equity Value | X24: Implied Share Price
B25: Calculating Implied Share Price | D25: Revenue | E25: EBITDA | F25: P/E | H25: Revenue | I25: EBITDA | J25: EPS | L25: Revenue | M25: EBITDA | N25: Net Income | P25: Cash | Q25: Debt | R25: Shares | T25: Revenue | U25: EBITDA | V25: Net Income | X25: Revenue | Y25: EBITDA | Z25: Net Income
B26: Minimum | D26: =MIN(Y13:Y19) -> 0.41478126 | E26: =MIN(AA13:AA19) -> 6.9796743 | F26: =MIN(AC13:AC19) -> -10.660498 | H26: =$K$11 -> 10588 | I26: =$M$11 -> 2946 | J26: 14.64 | L26: =H26*D26 -> 4391.704 | M26: =I26*E26 -> 20562.12 | P26: =DCF!$R$150 -> 1984.336 | Q26: =DCF!$R$151 -> 1575.8 | R26: 116.37023 | T26: =L26+P26-Q26 -> 4800.24 | U26: =M26+P26-Q26 -> 20970.656 | V26: =J26*R26*F26 -> -18161.865 | X26: =T26/$R26 -> 41.249725 | Y26: =U26/$R26 -> 180.20637 | Z26: =V26/$R26 -> -156.06968
B27: Mean | D27: =Y21 -> 1.8208457 | E27: =AA21 -> 12.515682 | F27: =AC21 -> 20.75958 | H27: =$K$11 -> 10588 | I27: =$M$11 -> 2946 | J27: 14.64 | L27: =H27*D27 -> 19279.115 | M27: =I27*E27 -> 36871.2 | P27: =DCF!$R$150 -> 1984.336 | Q27: =DCF!$R$151 -> 1575.8 | R27: 116.37023 | T27: =L27+P27-Q27 -> 19687.651 | U27: =M27+P27-Q27 -> 37279.736 | V27: =J27*R27*F27 -> 35367.27 | X27: =T27/$R27 -> 169.18116 | Y27: =U27/$R27 -> 320.35458 | Z27: =V27/$R27 -> 303.92025
B28: Median | D28: =Y22 -> 1.8028433 | E28: =AA22 -> 11.373124 | F28: =AC22 -> 17.909452 | H28: =$K$11 -> 10588 | I28: =$M$11 -> 2946 | J28: 14.64 | L28: =H28*D28 -> 19088.505 | M28: =I28*E28 -> 33505.222 | P28: =DCF!$R$150 -> 1984.336 | Q28: =DCF!$R$151 -> 1575.8 | R28: 116.37023 | T28: =L28+P28-Q28 -> 19497.041 | U28: =M28+P28-Q28 -> 33913.758 | V28: =J28*R28*F28 -> 30511.62 | X28: =T28/$R28 -> 167.5432 | Y28: =U28/$R28 -> 291.42984 | Z28: =V28/$R28 -> 262.19438
B29: Maximum | D29: =MAX(Y13:Y19) -> 3.3265194 | E29: =MAX(AA13:AA19) -> 18.91659 | F29: =MAX(AC13:AC19) -> 43.832045 | H29: =$K$11 -> 10588 | I29: =$M$11 -> 2946 | J29: 14.64 | L29: =H29*D29 -> 35221.187 | M29: =I29*E29 -> 55728.274 | P29: =DCF!$R$150 -> 1984.336 | Q29: =DCF!$R$151 -> 1575.8 | R29: 116.37023 | T29: =L29+P29-Q29 -> 35629.723 | U29: =M29+P29-Q29 -> 56136.81 | V29: =J29*R29*F29 -> 74674.91 | X29: =T29/$R29 -> 306.17558 | Y29: =U29/$R29 -> 482.39837 | Z29: =V29/$R29 -> 641.70114
B31: Database
D34: Current | E34: Share | F34: Market | G34: Enterprise | I34: Revenue | L34: EBITDA | N34: Net Income
B35: Ticker | C35: Company Name | D35: Price | E35: Count | F35: Cap | G35: Value | I35: 22 | J35: 23 | K35: 24 | L35: 23 | M35: 24 | N35: 23 | O35: 24
B36: LULU | C36: Lululemon | D36: 205.57 | E36: 116.37023 | F36: 24272.29 | G36: 23059.22 | I36: 8111 | J36: 9619 | K36: 10588 | L36: 2587 | M36: 2946 | N36: 1550 | O36: 1815
B37: COLM | C37: Columbia Sportswear | D37: 55.18 | E37: 58.5 | F37: 3022.21 | G37: 2502.31 | I37: 3464 | J37: 3487 | K37: 3370 | L37: 441 | M37: 322 | N37: 251 | O37: 223
B38: UAA | C38: Under Armour | D38: 5.04 | E38: 432.25 | F38: 2142.76 | G38: 2346.62 | I38: 5859 | J38: 5694 | K38: 5166 | L38: 375 | M38: 307 | N38: 232 | O38: -201
B39: ATZAF | C39: Artizia | D39: 57.48 | E39: 116.73 | F39: 6579.19 | G39: 6722.82 | I39: 1670.9 | J39: 1727.6 | K39: 1977.8 | L39: 241.8 | M39: 347.8 | N39: 58.4 | O39: 150.1
B40: NIKE | C40: Nike | D40: 78.06 | E40: 1487.6 | F40: 115287.09 | G40: 114937.33 | I40: 46792 | J40: 51191 | K40: 51386 | L40: 6016 | M40: 6839 | N40: 5070 | O40: 5700
B41: ADDDF | C41: Adidas | D41: 194.69 | E41: 178.56 | F41: 34895.2 | G41: 37627.2 | I41: 23658 | J41: 23165 | K41: 25618 | L41: 1463 | M41: 2618 | N41: -129 | O41: 818
B42: RL | C42: Ralph Lauren Corporation | D42: 294.64 | E42: 64 | F42: 17765.87 | G42: 17498.34 | I42: 6219 | J42: 6444 | K42: 6631 | L42: 967 | M42: 1045 | N42: 523 | O42: 646
B43: DKS | C43: Dick's Sporting Goods | D43: 226.01 | E43: 82.93 | F43: 18165.96 | G43: 19070.8 | I43: 12368 | J43: 12984 | K43: 13443 | L43: 1770 | M43: 1929 | N43: 1047 | O43: 1165
B44: GAP | C44: Gap | D44: 22.3 | E44: 384 | F44: 8319.38 | G44: 7987.39 | I44: 15616 | J44: 14889 | K44: 15086 | L44: 1144 | M44: 1600 | N44: 502 | O44: 844

Sheet DCF
B1: Allen Li
B2: Lululemon DCF
B4: Ticker | C4: LULU-US | F4: Current Price | I4: ='Trading Comp'!D36 -> 205.57 | K4: Green | L4: Reference other sheet
B5: Date | C5: =TODAY() -> 46037 | F5: Implied Share Price | I5: =R155 -> 231.98052 | K5: Red | L5: Reference estimations
B6: Year End | C6: 46022 | F6: Gain (Loss) | I6: =I5/I4-1 -> 0.1284746 | K6: Black | L6: Calculations
K7: Purple | L7: Repeat from cell
A9: x | B9: Assumptions
B10: Switches | F10: Conservative | J10: Base | N10: Optimistic
B11: Revenue | D11: 2 | F11: Revenue 26-29 | H11: 0.8 | J11: Revenue 27 | L11: 0.08 | N11: Revenue 26-29 | P11: 1.2
B12: EBIT | D12: 2 | F12: EBIT 26-29 | H12: 0.9 | J12: Revenue 29 | L12: 0.06 | N12: EBIT 26-29 | P12: 1.1
B13: WACC | D13: 2 | F13: SL Revenue | J13: EBIT 29 | L13: 0.21 | N13: SL Revenue
B14: TGR | D14: 2 | F14: SL EBIT | J14: SL Revenue | N14: SL EBIT
B15: Decay Factor | D15: 1 | J15: SL EBIT
F17: WACC | H17: =L17+0.5% -> 0.089126282 | J17: WACC | L17: =WACC!F21 -> 0.084126282 | N17: WACC | P17: =L17-0.5% -> 0.079126282
B18: WACC | D18: =CHOOSE($D$13,H17,L17,P17) -> 0.084126282 | F18: TGR | H18: 0.02 | J18: TGR | L18: 0.025 | N18: TGR | P18: 0.03
B19: TCG | D19: =CHOOSE(D14,H18,L18,P18) -> 0.025 | J19: Taxes | L19: =N128 -> 0.29833566
A21: x | B21: Revenue (12/31 CYE) | D21: 2015 | E21: 2016 | F21: 2017 | G21: 2018 | H21: 2019 | I21: 2020 | J21: 2021 | K21: 2022 | L21: 2023 | M21: 2024 | N21: 2025E | O21: 2026E | P21: 2027E | Q21: 2028E | R21: 2029E
H22: 67
B23: Company-operating stores | D23: 1516.323 | E23: 1704.357 | F23: 1837.065 | G23: 2126.363 | H23: 2501.067 | I23: 1658.807 | J23: 2821.497 | K23: 3648.127 | L23: =L38*L25 -> 4096.545 | M23: =M38*M25 -> 4509.1466 | N23: =N38*N25 -> 4780.7117 | O23: =O38*O25 -> 5110.8447 | P23: =P38*P25 -> 5422.3673 | Q23: =Q38*Q25 -> 5603.8724 | R23: =R38*R25 -> 6091.6193
B24: % growth | E24: =E23/D23-1 -> 0.12400656 | F24: =F23/E23-1 -> 0.077863969 | G24: =G23/F23-1 -> 0.15747837 | H24: =H23/G23-1 -> 0.17621827 | I24: =I23/H23-1 -> -0.33676027 | J24: =J23/I23-1 -> 0.7009194 | K24: =K23/J23-1 -> 0.29297568 | L24: =L23/K23-1 -> 0.12291731 | ... R24: =R23/Q23-1 -> 0.087037473
B25: % of total sales | D25: =D23/D35 -> 0.7358923 | E25: =E23/E35 -> 0.72699318 | F25: =F23/F35 -> 0.69344639 | G25: =G23/G35 -> 0.64664134 | H25: =H23/H35 -> 0.62851997 | I25: =I23/I35 -> 0.37684066 | J25: =J23/J35 -> 0.45096208 | K25: =K23/K35 -> 0.44980197 | L25: =AVERAGE($I$25:$K$25) -> 0.42586824 | M25: =AVERAGE($I$25:$K$25) -> 0.42586824 | N25: =AVERAGE($I$25:$M$25) -> 0.42586824 | O25: =AVERAGE($I$25:$M$25) -> 0.42586824 | P25: =AVERAGE($I$25:$M$25) -> 0.42586824 | Q25: =AVERAGE($I$25:$M$25) -> 0.42586824 | R25: =AVERAGE($I$25:$M$25) -> 0.42586824
B27: Direct to Consumer | D27: 401.525 | E27: 453.287 | F27: 577.59 | G27: 858.856 | H27: 1137.822 | I27: 2284.068 | J27: 2777.944 | K27: 3699.791 | L27: =L38*L29 -> 4550.1036 | M27: =M38*M29 -> 5008.3873 | N27: =N38*N29 -> 5310.0194 | O27: =O38*O29 -> 5676.7039 | P27: =P38*P29 -> 6022.7175 | Q27: =Q38*Q29 -> 6224.3183 | R27: =R38*R29 -> 6766.0672
B28: % growth | E28: =E27/D27-1 -> 0.12891352 | F28: =F27/E27-1 -> 0.27422582 | G28: =G27/F27-1 -> 0.4869648 | H28: =H27/G27-1 -> 0.32481114 | I28: =I27/H27-1 -> 1.0074036 | J28: =J27/I27-1 -> 0.21622649 | K28: =K27/J27-1 -> 0.33184506 | L28: =L27/K27-1 -> 0.22982719 | ... R28: =R27/Q27-1 -> 0.087037473
B29: % of total sales | D29: =D27/D35 -> 0.19486558 | E29: =E27/E35 -> 0.19334949 | F29: =F27/F35 -> 0.21802587 | G29: =G27/G35 -> 0.26118391 | H29: =H27/H35 -> 0.2859355 | I29: =I27/I35 -> 0.51888478 | J29: =J27/J35 -> 0.44400097 | K29: =K27/K35 -> 0.45617197 | L29: =AVERAGE($I$29:$K$29) -> 0.47301924 | M29: =AVERAGE($I$29:$K$29) -> 0.47301924 | N29: =AVERAGE($I$29:$M$29) -> 0.47301924 | O29: =AVERAGE($I$29:$M$29) -> 0.47301924 | P29: =AVERAGE($I$29:$M$29) -> 0.47301924 | Q29: =AVERAGE($I$29:$M$29) -> 0.47301924 | R29: =AVERAGE($I$29:$M$29) -> 0.47301924
L30: .
B31: Other | D31: 142.675 | E31: 186.748 | F31: 234.526 | G31: 303.1 | H31: 340.407 | I31: 459.004 | J31: 657.176 | K31: 762.6 | L31: =L38*L33 -> 972.62947 | M31: =M38*M33 -> 1070.5921 | N31: =N38*N33 -> 1135.069 | O31: =O38*O33 -> 1213.4514 | P31: =P38*P33 -> 1287.4152 | Q31: =Q38*Q33 -> 1330.5094 | R31: =R38*R33 -> 1446.3135
B32: % growth | E32: =E31/D31-1 -> 0.30890485 | F32: =F31/E31-1 -> 0.2558421 | G32: =G31/F31-1 -> 0.29239402 | H32: =H31/G31-1 -> 0.12308479 | I32: =I31/H31-1 -> 0.34839765 | J32: =J31/I31-1 -> 0.43174351 | K32: =K31/J31-1 -> 0.16041974 | L32: =L31/K31-1 -> 0.27541237 | ... R32: =R31/Q31-1 -> 0.087037473
B33: % of total sales | D33: =D31/D35 -> 0.069242129 | E33: =E31/E35 -> 0.079657327 | F33: =F31/F35 -> 0.088527737 | G33: =G31/G35 -> 0.092174756 | H33: =H31/H35 -> 0.085544528 | I33: =I31/I35 -> 0.10427456 | J33: =J31/J35 -> 0.10503696 | K33: =K31/K35 -> 0.094026054 | L33: =AVERAGE($I$33:$K$33) -> 0.10111252 | M33: =AVERAGE($I$33:$K$33) -> 0.10111252 | N33: =AVERAGE($I$33:$M$33) -> 0.10111252 | O33: =AVERAGE($I$33:$M$33) -> 0.10111252 | P33: =AVERAGE($I$33:$M$33) -> 0.10111252 | Q33: =AVERAGE($I$33:$M$33) -> 0.10111252 | R33: =AVERAGE($I$33:$M$33) -> 0.10111252
B35: Total | D35: =SUM(D23,D27,D31) -> 2060.523 | E35: =SUM(E23,E27,E31) -> 2344.392 | F35: =SUM(F23,F27,F31) -> 2649.181 | G35: =SUM(G23,G27,G31) -> 3288.319 | H35: =SUM(H23,H27,H31) -> 3979.296 | I35: =SUM(I23,I27,I31) -> 4401.879 | J35: =SUM(J23,J27,J31) -> 6256.617 | K35: =SUM(K23,K27,K31) -> 8110.518 | ... R35: =SUM(R23,R27,R31) -> 14304
B36: % growth | D36: -- | E36: =E35/D35-1 -> 0.13776551 | F36: =F35/E35-1 -> 0.13000769 | G36: =G35/F35-1 -> 0.24125871 | H36: =H35/G35-1 -> 0.21013077 | I36: =I35/H35-1 -> 0.10619542 | J36: =J35/I35-1 -> 0.42135143 | K36: =K35/J35-1 -> 0.29631045 | L36: =L35/K35-1 -> 0.18602511 | ... R36: =R35/Q35-1 -> 0.087037473
B38: Revenue | D38: =IS!B10 -> 2060.523 | E38: =IS!C10 -> 2344.392 | F38: =IS!D10 -> 2649.181 | G38: =IS!E10 -> 3288.319 | H38: =IS!F10 -> 3979.296 | I38: =IS!G10 -> 4401.879 | J38: =IS!H10 -> 6256.617 | K38: =IS!I10 -> 8110.518 | ... M38: =IS!K10 -> 10588.126 | N38: =IS!G60 -> 11225.8 | O38: =IS!H60 -> 12001 | P38: =IS!I60 -> 12732.5 | Q38: =IS!J60 -> 13158.7 | R38: =IS!K60 -> 14304
B39: % growth | E39: =E38/D38-1 -> 0.13776551 | F39: =F38/E38-1 -> 0.13000769 | G39: =G38/F38-1 -> 0.24125871 | H39: =H38/G38-1 -> 0.21013077 | I39: =I38/H38-1 -> 0.10619542 | J39: =J38/I38-1 -> 0.42135143 | K39: =K38/J38-1 -> 0.29631045 | L39: =L38/K38-1 -> 0.18602511 | ... R39: =R38/Q38-1 -> 0.087037473
B41: EBIT (12/31 CYE) | D41: 2015 | E41: 2016 | F41: 2017 | G41: 2018 | H41: 2019 | I41: 2020 | J41: 2021 | K41: 2022 | L41: 2023 | M41: 2024 | N41: 2025E | O41: 2026E | P41: 2027E | Q41: 2028E | R41: 2029E
B43: Company-operating stores | D43: =D55*D25 -> 262.80038 | E43: =E55*E25 -> 312.20868 | F43: =F55*F25 -> 343.88492 | G43: =G55*G25 -> 455.52196 | H43: =H55*H25 -> 559.7712 | I43: =I55*I25 -> 307.43867 | J43: =J55*J25 -> 623.73106 | K43: =K55*K25 -> 779.81089 | ... R43: =R55*R25 -> 1344.8919
B44: % of sales | D44: =D43/D23 -> 0.17331425 | E44: =E43/E23 -> 0.18318268 | F44: =F43/F23 -> 0.18719257 | G44: =G43/G23 -> 0.21422587 | H44: =H43/H23 -> 0.22381296 | I44: =I43/I23 -> 0.18533722 | J44: =J43/J23 -> 0.22106388 | K44: =K43/K23 -> 0.21375651 | ... R44: =R43/R23 -> 0.2207774
B45: % of total EBIT | D45: =D43/$D$55 -> 0.7358923 | E45: =E43/E55 -> 0.72699318 | F45: =F43/F55 -> 0.69344639 | G45: =G43/G55 -> 0.64664134 | H45: =H43/H55 -> 0.62851997 | I45: =I43/I55 -> 0.37684066 | J45: =J43/J55 -> 0.45096208 | K45: =K43/K55 -> 0.44980197 | L45: =L43/L55 -> 0.42586824 | ... R45: =R43/R55 -> 0.42586824
B47: Direct to Consumer | D47: =D55*D29 -> 69.590005 | E47: =E55*E29 -> 83.034326 | F47: =F55*F29 -> 108.12056 | G47: =G55*G29 -> 183.98917 | H47: =H55*H29 -> 254.65931 | I47: =I55*I29 -> 423.3228 | J47: =J55*J29 -> 614.10307 | K47: =K55*K29 -> 790.8544 | ... R47: =R55*R29 -> 1493.7948
B48: % of sales | D48: =D47/D27 -> 0.17331425 | E48: =E47/E27 -> 0.18318268 | F48: =F47/F27 -> 0.18719257 | G48: =G47/G27 -> 0.21422587 | H48: =H47/H27 -> 0.22381296 | I48: =I47/I27 -> 0.18533722 | J48: =J47/J27 -> 0.22106388 | K48: =K47/K27 -> 0.21375651 | ... R48: =R47/R27 -> 0.2207774
B49: % of total EBIT | D49: =D47/D$55 -> 0.19486558 | E49: =E47/E$55 -> 0.19334949 | F49: =F47/F$55 -> 0.21802587 | G49: =G47/G$55 -> 0.26118391 | H49: =H47/H$55 -> 0.2859355 | I49: =I47/I$55 -> 0.51888478 | J49: =J47/J$55 -> 0.44400097 | K49: =K47/K$55 -> 0.45617197 | ... R49: =R47/R$55 -> 0.47301924
B51: Other | D51: =D55*D33 -> 24.727611 | E51: =E55*E33 -> 34.208998 | F51: =F55*F33 -> 43.901525 | G51: =G55*G33 -> 64.931861 | H51: =H55*H33 -> 76.187497 | I51: =I55*I33 -> 85.070524 | J51: =J55*J33 -> 145.27787 | K51: =K55*K33 -> 163.01071 | ... R51: =R55*R33 -> 319.31335
...

Sheet Consolidated
B2: Consolidated DCF
A4: x | B4: Assumptions
B5: WACC | D5: =WACC -> 0.084126282
B6: TGR | D6: =TGR -> 0.025
A9: x | B9: DCF | D9: 2015 | E9: 2016 | F9: 2017 | G9: 2018 | H9: 2019 | I9: 2020 | J9: 2021 | K9: 2022 | L9: 2023 | M9: 2024 | N9: 2025 | O9: 2026 | P9: 2027 | Q9: 2028 | R9: 2029
A11: x | B11: Revenue | D11: ='Company-operated store DCF'!D11+'Direct to Consumer DCF'!D11+'Other DCF'!D11 -> 2060.523 | E11: ='Company-operated store DCF'!E11+'Direct to Consumer DCF'!E11+'Other DCF'!E11 -> 2344.392 | F11: ='Company-operated store DCF'!F11+'Direct to Consumer DCF'!F11+'Other DCF'!F11 -> 2649.181 | G11: ='Company-operated store DCF'!G11+'Direct to Consumer DCF'!G11+'Other DCF'!G11 -> 3288.319 | H11: ='Company-operated store DCF'!H11+'Direct to Consumer DCF'!H11+'Other DCF'!H11 -> 3979.296 | I11: ='Company-operated store DCF'!I11+'Direct to Consumer DCF'!I11+'Other DCF'!I11 -> 4401.879 | J11: ='Company-operated store DCF'!J11+'Direct to Consumer DCF'!J11+'Other DCF'!J11 -> 6256.617 | K11: ='Company-operated store DCF'!K11+'Direct to Consumer DCF'!K11+'Other DCF'!K11 -> 8110.518 | ... R11: ='Company-operated store DCF'!R11+'Direct to Consumer DCF'!R11+'Other DCF'!R11 -> 14801.337
B12: % growth | E12: =E11/D11-1 -> 0.13776551 | F12: =F11/E11-1 -> 0.13000769 | G12: =G11/F11-1 -> 0.24125871 | H12: =H11/G11-1 -> 0.21013077 | I12: =I11/H11-1 -> 0.10619542 | J12: =J11/I11-1 -> 0.42135143 | K12: =K11/J11-1 -> 0.29631045 | L12: =L11/K11-1 -> 0.18602511 | M12: =M11/L11-1 -> 0.10071941 | N12: =OFFSET(N12,DCF!$D$11,0) -> 0.060225388 | O12: =OFFSET(O12,DCF!$D$11,0) -> 0.069055212 | P12: =OFFSET(P12,DCF!$D$11,0) -> 0.14501595 | Q12: =OFFSET(Q12,DCF!$D$11,0) -> 0.30453349 | R12: =OFFSET(R12,DCF!$D$11,0) -> 0.63952032
B13: Conservative | N13: 0.060225388 | O13: 0.062149691 | P13: 0.13051435 | Q13: 0.27408014 | R13: 0.57556829
B14: Base | N14: 0.060225388 | O14: 0.069055212 | P14: 0.14501595 | Q14: 0.30453349 | R14: 0.63952032
B15: Optimisitic | N15: 0.060225388 | O15: 0.082866255 | P15: 0.17401913 | Q15: 0.36544018 | R15: 0.76742438
B17: EBIT | D17: ='Company-operated store DCF'!D17+'Direct to Consumer DCF'!D17+'Other DCF'!D17 -> 357.118 | E17: ='Company-operated store DCF'!E17+'Direct to Consumer DCF'!E17+'Other DCF'!E17 -> 429.452 | F17: ='Company-operated store DCF'!F17+'Direct to Consumer DCF'!F17+'Other DCF'!F17 -> 495.907 | G17: ='Company-operated store DCF'!G17+'Direct to Consumer DCF'!G17+'Other DCF'!G17 -> 704.443 | H17: ='Company-operated store DCF'!H17+'Direct to Consumer DCF'!H17+'Other DCF'!H17 -> 890.618 | I17: ='Company-operated store DCF'!I17+'Direct to Consumer DCF'!I17+'Other DCF'!I17 -> 815.832 | J17: ='Company-operated store DCF'!J17+'Direct to Consumer DCF'!J17+'Other DCF'!J17 -> 1383.112 | K17: ='Company-operated store DCF'!K17+'Direct to Consumer DCF'!K17+'Other DCF'!K17 -> 1733.676 | ... R17: ='Company-operated store DCF'!R17+'Direct to Consumer DCF'!R17+'Other DCF'!R17 -> 3108.2807
B18: % of sales | E18: =E17/E11 -> 0.18318268 | F18: =F17/F11 -> 0.18719257 | G18: =G17/G11 -> 0.21422587 | H18: =H17/H11 -> 0.22381296 | I18: =I17/I11 -> 0.18533722 | J18: =J17/J11 -> 0.22106388 | K18: =K17/K11 -> 0.21375651 | L18: =L17/L11 -> 0.22950205 | M18: =M17/M11 -> 0.23609249 | N18: =OFFSET(N18,DCF!$D$11,0) -> 0.21809581 | O18: =OFFSET(O18,DCF!$D$11,0) -> 0.20282911 | P18: =OFFSET(P18,DCF!$D$11,0) -> 0.18863107 | Q18: =OFFSET(Q18,DCF!$D$11,0) -> 0.1754269 | R18: =OFFSET(R18,DCF!$D$11,0) -> 0.16314701
B19: Conservative | N19: 0.21809581 | O19: 0.19628623 | P19: 0.17665761 | Q19: 0.15899185 | R19: 0.14309266
B20: Base | N20: 0.21809581 | O20: 0.20282911 | P20: 0.18863107 | Q20: 0.1754269 | R20: 0.16314701
B21: Optimisitic | N21: 0.21809581 | O21: 0.20688569 | P21: 0.19240369 | Q21: 0.17893543 | R21: 0.16640995
B23: Taxes | D23: ='Company-operated store DCF'!D23+'Direct to Consumer DCF'!D23+'Other DCF'!D23 -> 99.284997 | E23: ='Company-operated store DCF'!E23+'Direct to Consumer DCF'!E23+'Other DCF'!E23 -> 121.24609 | F23: ='Company-operated store DCF'!F23+'Direct to Consumer DCF'!F23+'Other DCF'!F23 -> 217.05297 | G23: ='Company-operated store DCF'!G23+'Direct to Consumer DCF'!G23+'Other DCF'!G23 -> 227.95194 | H23: ='Company-operated store DCF'!H23+'Direct to Consumer DCF'!H23+'Other DCF'!H23 -> 249.89602 | I23: ='Company-operated store DCF'!I23+'Direct to Consumer DCF'!I23+'Other DCF'!I23 -> 229.44758 | J23: ='Company-operated store DCF'!J23+'Direct to Consumer DCF'!J23+'Other DCF'!J23 -> 371.78363 | K23: ='Company-operated store DCF'!K23+'Direct to Consumer DCF'!K23+'Other DCF'!K23 -> 621.58048 | ... R23: ='Company-operated store DCF'!R23+'Direct to Consumer DCF'!R23+'Other DCF'!R23 -> 927.31097
B24: % tax rate | D24: =DCF!D61 -> 0.27801734 | E24: =DCF!E61 -> 0.28232745 | F24: =DCF!F61 -> 0.43768886 | G24: =DCF!G61 -> 0.32359175 | H24: =DCF!H61 -> 0.28058721 | I24: =DCF!I61 -> 0.28124367 | J24: =DCF!J61 -> 0.26880226 | K24: =DCF!K61 -> 0.35853324 | ... R24: =DCF!R61 -> 0.29833566
B26: EBIAT | D26: =D17-D23 -> 257.833 | E26: =E17-E23 -> 308.20591 | F26: =F17-F23 -> 278.85403 | G26: =G17-G23 -> 476.49106 | H26: =H17-H23 -> 640.72198 | I26: =I17-I23 -> 586.38442 | J26: =J17-J23 -> 1011.3284 | K26: =K17-K23 -> 1112.0955 | ... R26: =R17-R23 -> 2180.9697
B28: D&A | D28: ='Company-operated store DCF'!D28+'Direct to Consumer DCF'!D28+'Other DCF'!D28 -> 73.383 | E28: ='Company-operated store DCF'!E28+'Direct to Consumer DCF'!E28+'Other DCF'!E28 -> 87.697 | F28: ='Company-operated store DCF'!F28+'Direct to Consumer DCF'!F28+'Other DCF'!F28 -> 108.235 | G28: ='Company-operated store DCF'!G28+'Direct to Consumer DCF'!G28+'Other DCF'!G28 -> 122.484 | H28: ='Company-operated store DCF'!H28+'Direct to Consumer DCF'!H28+'Other DCF'!H28 -> 161.933 | I28: ='Company-operated store DCF'!I28+'Direct to Consumer DCF'!I28+'Other DCF'!I28 -> 185.478 | J28: ='Company-operated store DCF'!J28+'Direct to Consumer DCF'!J28+'Other DCF'!J28 -> 224.206 | K28: ='Company-operated store DCF'!K28+'Direct to Consumer DCF'!K28+'Other DCF'!K28 -> 291.791 | ... R28: ='Company-operated store DCF'!R28+'Direct to Consumer DCF'!R28+'Other DCF'!R28 -> 554.1071
B29: % of sales | D29: =D28/D11 -> 0.035613774 | E29: =E28/E11 -> 0.03740714 | F29: =F28/F11 -> 0.040856023 | G29: =G28/G11 -> 0.037248211 | H29: =H28/H11 -> 0.040693882 | I29: =I28/I11 -> 0.042136097 | J29: =J28/J11 -> 0.035835021 | K29: =K28/K11 -> 0.035976864 | ... R29: =R28/R11 -> 0.037436288
B31: CapEx | D31: ='Company-operated store DCF'!D31+'Direct to Consumer DCF'!D31+'Other DCF'!D31 -> 143.487 | E31: ='Company-operated store DCF'!E31+'Direct to Consumer DCF'!E31+'Other DCF'!E31 -> 149.511 | F31: ='Company-operated store DCF'!F31+'Direct to Consumer DCF'!F31+'Other DCF'!F31 -> 157.864 | G31: ='Company-operated store DCF'!G31+'Direct to Consumer DCF'!G31+'Other DCF'!G31 -> 225.807 | H31: ='Company-operated store DCF'!H31+'Direct to Consumer DCF'!H31+'Other DCF'!H31 -> 283.048 | I31: ='Company-operated store DCF'!I31+'Direct to Consumer DCF'!I31+'Other DCF'!I31 -> 229.226 | J31: ='Company-operated store DCF'!J31+'Direct to Consumer DCF'!J31+'Other DCF'!J31 -> 394.502 | K31: ='Company-operated store DCF'!K31+'Direct to Consumer DCF'!K31+'Other DCF'!K31 -> 638.657 | ... R31: ='Company-operated store DCF'!R31+'Direct to Consumer DCF'!R31+'Other DCF'!R31 -> 787
B32: % of sales | D32: =D31/D11 -> 0.069636204 | E32: =E31/E11 -> 0.063773891 | F32: =F31/F11 -> 0.059589737 | G32: =G31/G11 -> 0.068669433 | H32: =H31/H11 -> 0.07113017 | I32: =I31/I11 -> 0.05207458 | J32: =J31/J11 -> 0.063053564 | K32: =K31/K11 -> 0.078744292 | ... R32: =R31/R11 -> 0.053170873
B34: Change in NWC | D34: ='Company-operated store DCF'!D34+'Direct to Consumer DCF'!D34+'Other DCF'!D34 -> 59.743 | E34: ='Company-operated store DCF'!E34+'Direct to Consumer DCF'!E34+'Other DCF'!E34 -> -0.603 | F34: ='Company-operated store DCF'!F34+'Direct to Consumer DCF'!F34+'Other DCF'!F34 -> -104.628 | G34: ='Company-operated store DCF'!G34+'Direct to Consumer DCF'!G34+'Other DCF'!G34 -> -112.875 | H34: ='Company-operated store DCF'!H34+'Direct to Consumer DCF'!H34+'Other DCF'!H34 -> 194.071 | I34: ='Company-operated store DCF'!I34+'Direct to Consumer DCF'!I34+'Other DCF'!I34 -> 47.549 | J34: ='Company-operated store DCF'!J34+'Direct to Consumer DCF'!J34+'Other DCF'!J34 -> -129.131 | K34: ='Company-operated store DCF'!K34+'Direct to Consumer DCF'!K34+'Other DCF'!K34 -> 596.992 | ... R34: ='Company-operated store DCF'!R34+'Direct to Consumer DCF'!R34+'Other DCF'!R34 -> 275.57884
B35: % of sales | D35: =D34/D11 -> 0.028994095 | E35: =E34/E11 -> -0.00025720955 | F35: =F34/F11 -> -0.03949447 | G35: =G34/G11 -> -0.034326049 | H35: =H34/H11 -> 0.048770184 | I35: =I34/I11 -> 0.010801978 | J35: =J34/J11 -> -0.020639109 | K35: =K34/K11 -> 0.073607136 | ... R35: =R34/R11 -> 0.01861851
B37: Unlevered FCF | D37: =D26+D28-D31-D34 -> 127.986 | E37: =E26+E28-E31-E34 -> 246.99491 | F37: =F26+F28-F31-F34 -> 333.85303 | G37: =G26+G28-G31-G34 -> 486.04306 | H37: =H26+H28-H31-H34 -> 325.53598 | I37: =I26+I28-I31-I34 -> 495.08742 | J37: =J26+J28-J31-J34 -> 970.16337 | K37: =K26+K28-K31-K34 -> 168.23752 | ... R37: =R26+R28-R31-R34 -> 1672.498
B38: PV FCF | N38: =(N37*N40)/(1+D5)^N41 -> 49.050022 | O38: =O37/(1+$D$5)^O41 -> 1188.8815 | P38: =P37/(1+$D$5)^P41 -> 1204.9802 | Q38: =Q37/(1+$D$5)^Q41 -> 1192.7592 | R38: =R37/(1+$D$5)^R41 -> 1258.5058
B40: Period | N40: =DCF!N144 -> 0.041666667
B41: Discount Period | N41: =DCF!N145 -> 0.020833333 | O41: =DCF!O145 -> 0.52083333 | P41: =DCF!P145 -> 1.5208333 | Q41: =DCF!Q145 -> 2.5208333 | R41: =DCF!R145 -> 3.5208333
B43: Terminal Value | R43: =(R37*(1+D6))/(D5-D6) -> 28994.051
B44: PV TV | R44: =R43/(1+WACC)^R41 -> 21817.175
B46: Enterprise Value | R46: =SUM(N38:R38)+R44 -> 26711.352
B47: (+) Cash | R47: =DCF!R150 -> 1984.336
B48: (-) Debt | R48: =DCF!R151 -> 1575.8
B49: Equity Value | R49: =R46+R47-R48 -> 27119.888
B51: Diluted Shares | R51: =Shares!E14 -> 116.37023
B52: Implied Stock Price | R52: =R49/R51 -> 233.04833

Sheet Company-operated store DCF
B2: Company-operated stores DCF
A4: x | B4: Assumptions
B5: WACC | D5: =WACC -> 0.084126282
B6: TGR | D6: =TGR -> 0.025
A9: x | B9: DCF | D9: 2015 | E9: 2016 | F9: 2017 | G9: 2018 | H9: 2019 | I9: 2020 | J9: 2021 | K9: 2022 | L9: 2023 | M9: 2024 | N9: 2025 | O9: 2026 | P9: 2027 | Q9: 2028 | R9: 2029
A11: x | B11: Revenue | D11: =DCF!D23 -> 1516.323 | E11: =DCF!E23 -> 1704.357 | F11: =DCF!F23 -> 1837.065 | G11: =DCF!G23 -> 2126.363 | H11: =DCF!H23 -> 2501.067 | I11: =DCF!I23 -> 1658.807 | J11: =DCF!J23 -> 2821.497 | K11: =DCF!K23 -> 3648.127 | ... M11: =DCF!M23 -> 4509.1466 | N11: =M11*(1+N12) -> 4780.7117 | O11: =N11*(1+O12) -> 5110.8447 | P11: =O11*(1+P12) -> 5519.7123 | Q11: =P11*(1+Q12) -> 5946.6219 | R11: =Q11*(1+R12) -> 6303.4192
B12: % growth | E12: =DCF!E24 -> 0.12400656 | F12: =DCF!F24 -> 0.077863969 | G12: =DCF!G24 -> 0.15747837 | H12: =DCF!H24 -> 0.17621827 | I12: =DCF!I24 -> -0.33676027 | J12: =DCF!J24 -> 0.7009194 | K12: =DCF!K24 -> 0.29297568 | L12: =DCF!L24 -> 0.12291731 | M12: =DCF!M24 -> 0.10071941 | N12: =OFFSET(N12,DCF!$D$11,0) -> 0.060225388 | O12: =OFFSET(O12,DCF!$D$11,0) -> 0.069055212 | P12: =OFFSET(P12,DCF!$D$11,0) -> 0.08 | Q12: =OFFSET(Q12,DCF!$D$11,0) -> 0.077342721 | R12: =OFFSET(R12,DCF!$D$11,0) -> 0.06
B13: Conservative | N13: =DCF!N117 -> 0.060225388 | O13: =DCF!O117 -> 0.05524417 | P13: =DCF!P117 -> 0.064 | Q13: =DCF!Q117 -> 0.061874177 | R13: =DCF!R117 -> 0.048
B14: Base | N14: =DCF!N118 -> 0.060225388 | O14: =DCF!O118 -> 0.069055212 | P14: =DCF!P118 -> 0.08 | Q14: =DCF!Q118 -> 0.077342721 | R14: =DCF!R118 -> 0.06
B15: Optimisitic | N15: =DCF!N119 -> 0.060225388 | O15: =DCF!O119 -> 0.082866255 | P15: =DCF!P119 -> 0.096 | Q15: =DCF!Q119 -> 0.092811266 | R15: =DCF!R119 -> 0.072
B17: EBIT | D17: =DCF!D43 -> 262.80038 | E17: =DCF!E43 -> 312.20868 | F17: =DCF!F43 -> 343.88492 | G17: =DCF!G43 -> 455.52196 | H17: =DCF!H43 -> 559.7712 | I17: =DCF!I43 -> 307.43867 | J17: =DCF!J43 -> 623.73106 | K17: =DCF!K43 -> 779.81089 | ... M17: =DCF!M43 -> 1064.5756 | N17: =N11*N18 -> 1042.6532 | O17: =O11*O18 -> 1100.4393 | P17: =P11*P18 -> 1178.6961 | Q17: =Q11*Q18 -> 1254.0579 | R17: =R11*R18 -> 1323.718
B18: % of sales | E18: =DCF!E44 -> 0.18318268 | F18: =DCF!F44 -> 0.18719257 | G18: =DCF!G44 -> 0.21422587 | H18: =DCF!H44 -> 0.22381296 | I18: =DCF!I44 -> 0.18533722 | J18: =DCF!J44 -> 0.22106388 | K18: =DCF!K44 -> 0.21375651 | L18: =DCF!L44 -> 0.22950205 | M18: =DCF!M44 -> 0.23609249 | N18: =OFFSET(N18,DCF!$D$12,0) -> 0.21809581 | O18: =OFFSET(O18,DCF!$D$12,0) -> 0.21531456 | P18: =OFFSET(P18,DCF!$D$12,0) -> 0.21354304 | Q18: =OFFSET(Q18,DCF!$D$12,0) -> 0.21088576 | R18: =OFFSET(R18,DCF!$D$12,0) -> 0.21
B19: Conservative | N19: =DCF!N123 -> 0.21809581 | O19: =DCF!O123 -> 0.19628623 | P19: =DCF!P123 -> 0.17665761 | Q19: =DCF!Q123 -> 0.15899185 | R19: =DCF!R123 -> 0.14309266
B20: Base | N20: =DCF!N124 -> 0.21809581 | O20: =DCF!O124 -> 0.21531456 | P20: =DCF!P124 -> 0.21354304 | Q20: =DCF!Q124 -> 0.21088576 | R20: =DCF!R124 -> 0.21
B21: Optimisitic | N21: =DCF!N125 -> 0.21809581 | O21: =DCF!O125 -> 0.23684601 | P21: =DCF!P125 -> 0.23489734 | Q21: =DCF!Q125 -> 0.23197434 | R21: =DCF!R125 -> 0.231
B23: Taxes | D23: =D24*D17 -> 73.063064 | E23: =E24*E17 -> 88.145079 | F23: =F24*F17 -> 150.5146 | G23: =G24*G17 -> 147.40315 | H23: =H24*H17 -> 157.06464 | I23: =I24*I17 -> 86.46518 | J23: =J24*J17 -> 167.66032 | K23: =K24*K17 -> 279.58812 | ... R23: =R24*R17 -> 394.91229
B24: % tax rate | D24: =DCF!D61 -> 0.27801734 | E24: =DCF!E61 -> 0.28232745 | F24: =DCF!F61 -> 0.43768886 | G24: =DCF!G61 -> 0.32359175 | H24: =DCF!H61 -> 0.28058721 | I24: =DCF!I61 -> 0.28124367 | J24: =DCF!J61 -> 0.26880226 | K24: =DCF!K61 -> 0.35853324 | ... R24: =DCF!R61 -> 0.29833566
B26: EBIAT | D26: =D17-D23 -> 189.73732 | E26: =E17-E23 -> 224.0636 | F26: =F17-F23 -> 193.37032 | G26: =G17-G23 -> 308.11881 | H26: =H17-H23 -> 402.70656 | I26: =I17-I23 -> 220.97349 | J26: =J17-J23 -> 456.07074 | K26: =K17-K23 -> 500.22276 | ... R26: =R17-R23 -> 928.80574
B28: D&A | D28: =DCF!D65 -> 54.001984 | E28: =DCF!E65 -> 63.755121 | F28: =DCF!F65 -> 75.05517 | G28: =DCF!G65 -> 79.203218 | H28: =DCF!H65 -> 101.77812 | I28: =DCF!I65 -> 69.895652 | J28: =DCF!J65 -> 101.1084 | K28: =DCF!K65 -> 131.24817 | ... R28: =DCF!R65 -> 235.97661
B29: % of sales | E29: =DCF!E66 -> 0.72699318 | F29: =DCF!F66 -> 0.69344639 | G29: =DCF!G66 -> 0.64664134 | H29: =DCF!H66 -> 0.62851997 | I29: =DCF!I66 -> 0.37684066 | J29: =DCF!J66 -> 0.45096208 | K29: =DCF!K66 -> 0.44980197 | L29: =DCF!L66 -> 0.42586824 | ... R29: =DCF!R66 -> 0.42586824
B31: CapEx | D31: =DCF!D82 -> 105.59098 | E31: =DCF!E82 -> 108.69348 | F31: =DCF!F82 -> 109.47022 | G31: =DCF!G82 -> 146.01614 | H31: =DCF!H82 -> 177.90132 | I31: =DCF!I82 -> 86.381678 | J31: =DCF!J82 -> 177.90544 | K31: =DCF!K82 -> 287.26918 | ... R31: =DCF!R82 -> 335.1583
B32: % of sales | D32: =DCF!D83 -> 0.7358923 | E32: =DCF!E83 -> 0.72699318 | F32: =DCF!F83 -> 0.69344639 | G32: =DCF!G83 -> 0.64664134 | H32: =DCF!H83 -> 0.62851997 | I32: =DCF!I83 -> 0.37684066 | J32: =DCF!J83 -> 0.45096208 | K32: =DCF!K83 -> 0.44980197 | ... R32: =DCF!R83 -> 0.42586824
B34: Change in NWC | D34: =DCF!D98 -> 43.964413 | E34: =DCF!E98 -> -0.43837689 | F34: =DCF!F98 -> -72.553909 | G34: =DCF!G98 -> -72.989641 | H34: =DCF!H98 -> 121.9775 | I34: =DCF!I98 -> 17.918397 | J34: =DCF!J98 -> -58.233184 | K34: =DCF!K98 -> 268.52818 | ... R34: =DCF!R98 -> 117.36027
B35: % of sales | D35: =DCF!D99 -> 0.028994095 | E35: =DCF!E99 -> -0.00025720955 | F35: =DCF!F99 -> -0.03949447 | G35: =DCF!G99 -> -0.034326049 | H35: =DCF!H99 -> 0.048770184 | I35: =DCF!I99 -> 0.010801978 | J35: =DCF!J99 -> -0.020639109 | K35: =DCF!K99 -> 0.073607136 | ... R35: =DCF!R99 -> 0.019265858
B37: Unlevered FCF | D37: =D26+D28-D31-D34 -> 94.183914 | E37: =E26+E28-E31-E34 -> 179.56362 | F37: =F26+F28-F31-F34 -> 231.50918 | G37: =G26+G28-G31-G34 -> 314.29553 | H37: =H26+H28-H31-H34 -> 204.60586 | I37: =I26+I28-I31-I34 -> 186.56907 | J37: =J26+J28-J31-J34 -> 437.50689 | K37: =K26+K28-K31-K34 -> 75.67357 | ... R37: =R26+R28-R31-R34 -> 712.26378
B38: PV FCF | N38: =(N37*N40)/(1+D5)^N41 -> 20.888847 | O38: =O37/(1+$D$5)^O41 -> 506.30688 | P38: =P37/(1+$D$5)^P41 -> 513.16279 | Q38: =Q37/(1+$D$5)^Q41 -> 507.95827 | R38: =R37/(1+$D$5)^R41 -> 535.95765
B40: Period | N40: =DCF!N144 -> 0.041666667
B41: Discount Period | N41: =DCF!N145 -> 0.020833333 | O41: =DCF!O145 -> 0.52083333 | P41: =DCF!P145 -> 1.5208333 | Q41: =DCF!Q145 -> 2.5208333 | R41: =DCF!R145 -> 3.5208333
B43: Terminal Value | R43: =(R37*(1+D6))/(D5-D6) -> 12347.646
B44: PV TV | R44: =R43/(1+WACC)^R41 -> 9291.242
B46: Enterprise Value | R46: =SUM(N38:R38)+R44 -> 11375.516

Sheet Direct to Consumer DCF
B2: Direct to Consumer DCF
A4: x | B4: Assumptions
B5: WACC | D5: =WACC -> 0.084126282
B6: TGR | D6: =TGR -> 0.025
A9: x | B9: DCF | D9: 2015 | E9: 2016 | F9: 2017 | G9: 2018 | H9: 2019 | I9: 2020 | J9: 2021 | K9: 2022 | L9: 2023 | M9: 2024 | N9: 2025 | O9: 2026 | P9: 2027 | Q9: 2028 | R9: 2029
A11: x | B11: Revenue | D11: =DCF!D27 -> 401.525 | E11: =DCF!E27 -> 453.287 | F11: =DCF!F27 -> 577.59 | G11: =DCF!G27 -> 858.856 | H11: =DCF!H27 -> 1137.822 | I11: =DCF!I27 -> 2284.068 | J11: =DCF!J27 -> 2777.944 | K11: =DCF!K27 -> 3699.791 | ... M11: =DCF!M27 -> 5008.3873 | N11: =M11*(1+N12) -> 5310.0194 | O11: =N11*(1+O12) -> 5676.7039 | P11: =O11*(1+P12) -> 6130.8402 | Q11: =P11*(1+Q12) -> 6605.0161 | R11: =Q11*(1+R12) -> 7001.317
B12: % growth | E12: =DCF!E28 -> 0.12891352 | F12: =DCF!F28 -> 0.27422582 | G12: =DCF!G28 -> 0.4869648 | H12: =DCF!H28 -> 0.32481114 | I12: =DCF!I28 -> 1.0074036 | J12: =DCF!J28 -> 0.21622649 | K12: =DCF!K28 -> 0.33184506 | L12: =DCF!L28 -> 0.22982719 | M12: =DCF!M28 -> 0.10071941 | N12: =OFFSET(N12,DCF!$D$11,0) -> 0.060225388 | O12: =OFFSET(O12,DCF!$D$11,0) -> 0.069055212 | P12: =OFFSET(P12,DCF!$D$11,0) -> 0.08 | Q12: =OFFSET(Q12,DCF!$D$11,0) -> 0.077342721 | R12: =OFFSET(R12,DCF!$D$11,0) -> 0.06
B13: Conservative | N13: =DCF!N117 -> 0.060225388 | O13: =DCF!O117 -> 0.05524417 | P13: =DCF!P117 -> 0.064 | Q13: =DCF!Q117 -> 0.061874177 | R13: =DCF!R117 -> 0.048
B14: Base | N14: =DCF!N118 -> 0.060225388 | O14: =DCF!O118 -> 0.069055212 | P14: =DCF!P118 -> 0.08 | Q14: =DCF!Q118 -> 0.077342721 | R14: =DCF!R118 -> 0.06
B15: Optimisitic | N15: =DCF!N119 -> 0.060225388 | O15: =DCF!O119 -> 0.082866255 | P15: =DCF!P119 -> 0.096 | Q15: =DCF!Q119 -> 0.092811266 | R15: =DCF!R119 -> 0.072
B17: EBIT | D17: =DCF!D47 -> 69.590005 | E17: =DCF!E47 -> 83.034326 | F17: =DCF!F47 -> 108.12056 | G17: =DCF!G47 -> 183.98917 | H17: =DCF!H47 -> 254.65931 | I17: =DCF!I47 -> 423.3228 | J17: =DCF!J47 -> 614.10307 | K17: =DCF!K47 -> 790.8544 | ... M17: =DCF!M47 -> 1182.4426 | N17: =N11*N18 -> 1158.093 | O17: =O11*O18 -> 1222.277 | P17: =P11*P18 -> 1309.1982 | Q17: =Q11*Q18 -> 1392.9038 | R17: =R11*R18 -> 1470.2766
B18: % of sales | D18: =DCF!D48 -> 0.17331425 | E18: =DCF!E48 -> 0.18318268 | F18: =DCF!F48 -> 0.18719257 | G18: =DCF!G48 -> 0.21422587 | H18: =DCF!H48 -> 0.22381296 | I18: =DCF!I48 -> 0.18533722 | J18: =DCF!J48 -> 0.22106388 | K18: =DCF!K48 -> 0.21375651 | ... M18: =DCF!M48 -> 0.23609249 | N18: =OFFSET(N18,DCF!$D$11,0) -> 0.21809581 | O18: =OFFSET(O18,DCF!$D$11,0) -> 0.21531456 | P18: =OFFSET(P18,DCF!$D$11,0) -> 0.21354304 | Q18: =OFFSET(Q18,DCF!$D$11,0) -> 0.21088576 | R18: =OFFSET(R18,DCF!$D$11,0) -> 0.21
B19: Conservative | N19: =DCF!N123 -> 0.21809581 | O19: =DCF!O123 -> 0.19628623 | P19: =DCF!P123 -> 0.17665761 | Q19: =DCF!Q123 -> 0.15899185 | R19: =DCF!R123 -> 0.14309266
B20: Base | N20: =DCF!N124 -> 0.21809581 | O20: =DCF!O124 -> 0.21531456 | P20: =DCF!P124 -> 0.21354304 | Q20: =DCF!Q124 -> 0.21088576 | R20: =DCF!R124 -> 0.21
B21: Optimisitic | N21: =DCF!N125 -> 0.21809581 | O21: =DCF!O125 -> 0.23684601 | P21: =DCF!P125 -> 0.23489734 | Q21: =DCF!Q125 -> 0.23197434 | R21: =DCF!R125 -> 0.231
B23: Taxes | D23: =D17*D24 -> 19.347228 | E23: =E17*E24 -> 23.442869 | F23: =F17*F24 -> 47.323163 | G23: =G17*G24 -> 59.537379 | H23: =H17*H24 -> 71.454144 | I23: =I17*I24 -> 119.05686 | J23: =J17*J24 -> 165.07229 | K23: =K17*K24 -> 283.54759 | ... R23: =R17*R24 -> 438.63593
B24: % tax rate | D24: =DCF!D61 -> 0.27801734 | E24: =DCF!E61 -> 0.28232745 | F24: =DCF!F61 -> 0.43768886 | G24: =DCF!G61 -> 0.32359175 | H24: =DCF!H61 -> 0.28058721 | I24: =DCF!I61 -> 0.28124367 | J24: =DCF!J61 -> 0.26880226 | K24: =DCF!K61 -> 0.35853324 | ... R24: =DCF!R61 -> 0.29833566
B26: EBIAT | D26: =D17-D23 -> 50.242777 | E26: =E17-E23 -> 59.591456 | F26: =F17-F23 -> 60.797393 | G26: =G17-G23 -> 124.4518 | H26: =H17-H23 -> 183.20516 | I26: =I17-I23 -> 304.26595 | J26: =J17-J23 -> 449.03077 | K26: =K17-K23 -> 507.30681 | ... R26: =R17-R23 -> 1031.6406
B28: D&A | D28: =DCF!D69 -> 14.299821 | E28: =DCF!E69 -> 16.95617 | F28: =DCF!F69 -> 23.59803 | G28: =DCF!G69 -> 31.99085 | H28: =DCF!H69 -> 46.302394 | I28: =DCF!I69 -> 96.241711 | J28: =DCF!J69 -> 99.547681 | K28: =DCF!K69 -> 133.10688 | ... R28: =DCF!R69 -> 262.10332
B29: % of sales | D29: =DCF!D70 -> 0 | E29: =DCF!E70 -> 0.18576106 | F29: =DCF!F70 -> 0.39170756 | G29: =DCF!G70 -> 0.35565761 | H29: =DCF!H70 -> 0.44736368 | I29: =DCF!I70 -> 1.0785472 | J29: =DCF!J70 -> 0.034350702 | K29: =DCF!K70 -> 0.3371168 | ... R29: =DCF!R70 -> 0.37285389
B31: CapEx | D31: =DCF!D86 -> 27.960677 | E31: =DCF!E86 -> 28.907876 | F31: =DCF!F86 -> 34.418436 | G31: =DCF!G86 -> 58.977154 | H31: =DCF!H86 -> 80.933472 | I31: =DCF!I86 -> 118.94188 | J31: =DCF!J86 -> 175.15927 | K31: =DCF!K86 -> 291.33742 | ... R31: =DCF!R86 -> 372.26614
B32: % of sales | D32: =DCF!D87 -> 0.19486558 | E32: =DCF!E87 -> 0.19334949 | F32: =DCF!F87 -> 0.21802587 | G32: =DCF!G87 -> 0.26118391 | H32: =DCF!H87 -> 0.2859355 | I32: =DCF!I87 -> 0.51888478 | J32: =DCF!J87 -> 0.44400097 | K32: =DCF!K87 -> 0.45617197 | ... R32: =DCF!R87 -> 0.47301924
B34: Change in NWC | D34: =DCF!D102 -> 11.641854 | E34: =DCF!E102 -> -0.11658974 | F34: =DCF!F102 -> -22.811611 | G34: =DCF!G102 -> -29.481133 | H34: =DCF!H102 -> 55.491789 | I34: =DCF!I102 -> 24.672452 | J34: =DCF!J102 -> -57.334289 | K34: =DCF!K102 -> 272.33102 | ... R34: =DCF!R102 -> 130.35409
B35: % of sales | D35: =DCF!D103 -> 0.028994095 | E35: =DCF!E103 -> -0.00025720955 | F35: =DCF!F103 -> -0.03949447 | G35: =DCF!G103 -> -0.034326049 | H35: =DCF!H103 -> 0.048770184 | I35: =DCF!I103 -> 0.010801978 | J35: =DCF!J103 -> -0.020639109 | K35: =DCF!K103 -> 0.073607136 | ... R35: =DCF!R103 -> 0.019265858
B37: Unlevered FCF | D37: =D26+D28-D31-D34 -> 24.940066 | E37: =E26+E28-E31-E34 -> 47.756341 | F37: =F26+F28-F31-F34 -> 72.788598 | G37: =G26+G28-G31-G34 -> 126.94662 | H37: =H26+H28-H31-H34 -> 93.082293 | I37: =I26+I28-I31-I34 -> 256.89332 | J37: =J26+J28-J31-J34 -> 430.75347 | K37: =K26+K28-K31-K34 -> 76.745243 | ... R37: =R26+R28-R31-R34 -> 791.12373
B38: PV FCF | N38: =(N37*N40)/(1+D5)^N41 -> 23.201604 | O38: =O37/(1+$D$5)^O41 -> 562.36383 | P38: =P37/(1+$D$5)^P41 -> 569.97881 | Q38: =Q37/(1+$D$5)^Q41 -> 564.19807 | R38: =R37/(1+$D$5)^R41 -> 595.29746
B40: Period | N40: =DCF!N144 -> 0.041666667
B41: Discount Period | N41: =DCF!N145 -> 0.020833333 | O41: =DCF!O145 -> 0.52083333 | P41: =DCF!P145 -> 1.5208333 | Q41: =DCF!Q145 -> 2.5208333 | R41: =DCF!R145 -> 3.5208333
B43: Terminal Value | R43: =(R37*(1+D6))/(D5-D6) -> 13714.744
B44: PV TV | R44: =R43/(1+WACC)^R41 -> 10319.944
B46: Enterprise Value | R46: =SUM(N38:R38)+R44 -> 12634.983

Sheet Other DCF
B2: Other DCF
A4: x | B4: Assumptions
B5: WACC | D5: =WACC -> 0.084126282
B6: TGR | D6: =TGR -> 0.025
A9: x | B9: DCF | D9: 2015 | E9: 2016 | F9: 2017 | G9: 2018 | H9: 2019 | I9: 2020 | J9: 2021 | K9: 2022 | L9: 2023 | M9: 2024 | N9: 2025 | O9: 2026 | P9: 2027 | Q9: 2028 | R9: 2029
A11: x | B11: Revenue | D11: =DCF!D31 -> 142.675 | E11: =DCF!E31 -> 186.748 | F11: =DCF!F31 -> 234.526 | G11: =DCF!G31 -> 303.1 | H11: =DCF!H31 -> 340.407 | I11: =DCF!I31 -> 459.004 | J11: =DCF!J31 -> 657.176 | K11: =DCF!K31 -> 762.6 | ... M11: =DCF!M31 -> 1070.5921 | N11: =M11*(1+N12) -> 1135.069 | O11: =N11*(1+O12) -> 1213.4514 | P11: =O11*(1+P12) -> 1310.5275 | Q11: =P11*(1+Q12) -> 1411.8873 | R11: =Q11*(1+R12) -> 1496.6005
B12: % growth | E12: =DCF!E28 -> 0.12891352 | F12: =DCF!F28 -> 0.27422582 | G12: =DCF!G28 -> 0.4869648 | H12: =DCF!H28 -> 0.32481114 | I12: =DCF!I28 -> 1.0074036 | J12: =DCF!J28 -> 0.21622649 | K12: =DCF!K28 -> 0.33184506 | L12: =DCF!L28 -> 0.22982719 | M12: =DCF!M28 -> 0.10071941 | N12: =OFFSET(N12,DCF!$D$11,0) -> 0.060225388 | O12: =OFFSET(O12,DCF!$D$11,0) -> 0.069055212 | P12: =OFFSET(P12,DCF!$D$11,0) -> 0.08 | Q12: =OFFSET(Q12,DCF!$D$11,0) -> 0.077342721 | R12: =OFFSET(R12,DCF!$D$11,0) -> 0.06
B13: Conservative | N13: =DCF!N117 -> 0.060225388 | O13: =DCF!O117 -> 0.05524417 | P13: =DCF!P117 -> 0.064 | Q13: =DCF!Q117 -> 0.061874177 | R13: =DCF!R117 -> 0.048
B14: Base | N14: =DCF!N118 -> 0.060225388 | O14: =DCF!O118 -> 0.069055212 | P14: =DCF!P118 -> 0.08 | Q14: =DCF!Q118 -> 0.077342721 | R14: =DCF!R118 -> 0.06
B15: Optimisitic | N15: =DCF!N119 -> 0.060225388 | O15: =DCF!O119 -> 0.082866255 | P15: =DCF!P119 -> 0.096 | Q15: =DCF!Q119 -> 0.092811266 | R15: =DCF!R119 -> 0.072
B17: EBIT | D17: =DCF!D51 -> 24.727611 | E17: =DCF!E51 -> 34.208998 | F17: =DCF!F51 -> 43.901525 | G17: =DCF!G51 -> 64.931861 | H17: =DCF!H51 -> 76.187497 | I17: =DCF!I51 -> 85.070524 | J17: =DCF!J51 -> 145.27787 | K17: =DCF!K51 -> 163.01071 | ... M17: =DCF!M51 -> 252.75876 | N17: =N11*N18 -> 247.55379 | O17: =O11*O18 -> 261.27375 | P17: =P11*P18 -> 279.85402 | Q17: =Q11*Q18 -> 297.74692 | R17: =R11*R18 -> 314.28611
B18: % of sales | D18: =DCF!D48 -> 0.17331425 | E18: =DCF!E48 -> 0.18318268 | F18: =DCF!F48 -> 0.18719257 | G18: =DCF!G48 -> 0.21422587 | H18: =DCF!H48 -> 0.22381296 | I18: =DCF!I48 -> 0.18533722 | J18: =DCF!J48 -> 0.22106388 | K18: =DCF!K48 -> 0.21375651 | ... M18: =DCF!M48 -> 0.23609249 | N18: =OFFSET(N18,DCF!$D$11,0) -> 0.21809581 | O18: =OFFSET(O18,DCF!$D$11,0) -> 0.21531456 | P18: =OFFSET(P18,DCF!$D$11,0) -> 0.21354304 | Q18: =OFFSET(Q18,DCF!$D$11,0) -> 0.21088576 | R18: =OFFSET(R18,DCF!$D$11,0) -> 0.21
B19: Conservative | N19: =DCF!N123 -> 0.21809581 | O19: =DCF!O123 -> 0.19628623 | P19: =DCF!P123 -> 0.17665761 | Q19: =DCF!Q123 -> 0.15899185 | R19: =DCF!R123 -> 0.14309266
B20: Base | N20: =DCF!N124 -> 0.21809581 | O20: =DCF!O124 -> 0.21531456 | P20: =DCF!P124 -> 0.21354304 | Q20: =DCF!Q124 -> 0.21088576 | R20: =DCF!R124 -> 0.21
B21: Optimisitic | N21: =DCF!N125 -> 0.21809581 | O21: =DCF!O125 -> 0.23684601 | P21: =DCF!P125 -> 0.23489734 | Q21: =DCF!Q125 -> 0.23197434 | R21: =DCF!R125 -> 0.231
B23: Taxes | D23: =D17*D24 -> 6.8747046 | E23: =E17*E24 -> 9.6581392 | F23: =F17*F24 -> 19.215208 | G23: =G17*G24 -> 21.011415 | H23: =H17*H24 -> 21.377237 | I23: =I17*I24 -> 23.925546 | J23: =J17*J24 -> 39.05102 | K23: =K17*K24 -> 58.444759 | ... R23: =R17*R24 -> 93.762752
B24: % tax rate | D24: =DCF!D61 -> 0.27801734 | E24: =DCF!E61 -> 0.28232745 | F24: =DCF!F61 -> 0.43768886 | G24: =DCF!G61 -> 0.32359175 | H24: =DCF!H61 -> 0.28058721 | I24: =DCF!I61 -> 0.28124367 | J24: =DCF!J61 -> 0.26880226 | K24: =DCF!K61 -> 0.35853324 | ... R24: =DCF!R61 -> 0.29833566
B26: EBIAT | D26: =D17-D23 -> 17.852906 | E26: =E17-E23 -> 24.550859 | F26: =F17-F23 -> 24.686316 | G26: =G17-G23 -> 43.920447 | H26: =H17-H23 -> 54.81026 | I26: =I17-I23 -> 61.144977 | J26: =J17-J23 -> 106.22685 | K26: =K17-K23 -> 104.56595 | ... R26: =R17-R23 -> 220.52335
B28: D&A | D28: =DCF!D73 -> 5.0811952 | E28: =DCF!E73 -> 6.9857086 | F28: =DCF!F73 -> 9.5817997 | G28: =DCF!G73 -> 11.289933 | H28: =DCF!H73 -> 13.852482 | I28: =DCF!I73 -> 19.340637 | J28: =DCF!J73 -> 23.549916 | K28: =DCF!K73 -> 27.435956 | ... R28: =DCF!R73 -> 56.027167
B29: % of sales | D29: =DCF!D70 -> 0 | E29: =DCF!E70 -> 0.18576106 | F29: =DCF!F70 -> 0.39170756 | G29: =DCF!G70 -> 0.35565761 | H29: =DCF!H70 -> 0.44736368 | I29: =DCF!I70 -> 1.0785472 | J29: =DCF!J70 -> 0.034350702 | K29: =DCF!K70 -> 0.3371168 | ... R29: =DCF!R70 -> 0.37285389
B31: CapEx | D31: =DCF!D90 -> 9.9353454 | E31: =DCF!E90 -> 11.909647 | F31: =DCF!F90 -> 13.975343 | G31: =DCF!G90 -> 20.813705 | H31: =DCF!H90 -> 24.213208 | I31: =DCF!I90 -> 23.902441 | J31: =DCF!J90 -> 41.437289 | K31: =DCF!K90 -> 60.050397 | ... R31: =DCF!R90 -> 79.575556
B32: % of sales | D32: =DCF!D87 -> 0.19486558 | E32: =DCF!E87 -> 0.19334949 | F32: =DCF!F87 -> 0.21802587 | G32: =DCF!G87 -> 0.26118391 | H32: =DCF!H87 -> 0.2859355 | I32: =DCF!I87 -> 0.51888478 | J32: =DCF!J87 -> 0.44400097 | K32: =DCF!K87 -> 0.45617197 | ... R32: =DCF!R87 -> 0.47301924
B34: Change in NWC | D34: =DCF!D106 -> 4.1367325 | E34: =DCF!E106 -> -0.048033368 | F34: =DCF!F106 -> -9.2624801 | G34: =DCF!G106 -> -10.404226 | H34: =DCF!H106 -> 16.601712 | I34: =DCF!I106 -> 4.9581511 | J34: =DCF!J106 -> -13.563527 | K34: =DCF!K106 -> 56.132802 | ... R34: =DCF!R106 -> 27.864472
B35: % of sales | D35: =DCF!D103 -> 0.028994095 | E35: =DCF!E103 -> -0.00025720955 | F35: =DCF!F103 -> -0.03949447 | G35: =DCF!G103 -> -0.034326049 | H35: =DCF!H103 -> 0.048770184 | I35: =DCF!I103 -> 0.010801978 | J35: =DCF!J103 -> -0.020639109 | K35: =DCF!K103 -> 0.073607136 | ... R35: =DCF!R103 -> 0.019265858
B37: Unlevered FCF | D37: =D26+D28-D31-D34 -> 8.8620234 | E37: =E26+E28-E31-E34 -> 19.674955 | F37: =F26+F28-F31-F34 -> 29.555253 | G37: =G26+G28-G31-G34 -> 44.8009 | H37: =H26+H28-H31-H34 -> 27.847822 | I37: =I26+I28-I31-I34 -> 51.625023 | J37: =J26+J28-J31-J34 -> 101.90301 | K37: =K26+K28-K31-K34 -> 15.81871 | ... R37: =R26+R28-R31-R34 -> 169.11049
B38: PV FCF | N38: =(N37*N40)/(1+D5)^N41 -> 4.9595715 | O38: =O37/(1+$D$5)^O41 -> 120.21081 | P38: =P37/(1+$D$5)^P41 -> 121.83859 | Q38: =Q37/(1+$D$5)^Q41 -> 120.6029 | R38: =R37/(1+$D$5)^R41 -> 127.2507
B40: Period | N40: =DCF!N144 -> 0.041666667
B41: Discount Period | N41: =DCF!N145 -> 0.020833333 | O41: =DCF!O145 -> 0.52083333 | P41: =DCF!P145 -> 1.5208333 | Q41: =DCF!Q145 -> 2.5208333 | R41: =DCF!R145 -> 3.5208333
B43: Terminal Value | R43: =(R37*(1+D6))/(D5-D6) -> 2931.6617
B44: PV TV | R44: =R43/(1+WACC)^R41 -> 2205.9896
B46: Enterprise Value | R46: =SUM(N38:R38)+R44 -> 2700.8522

Sheet WACC
B1: in millions
B2: WACC
B3: (% of Equity * cost of equity) + (% of debt * cost of debt) * (1 - Tax) | H3: Beta
B4: Cost of Equity = Risk Free Rate + (Beta * Market Risk Premium) | H4: Use from source
B6: WACC | H6: Market Risk Premium
B7: Market Cap | F7: 27098.24 | H7: damodaran Online
B8: % of Equity | F8: =F7/(F7+F14) -> 0.94504437
B9: Cost of Equity | F9: =F10+(F11*F12) -> 0.086776 | H9: Risk Free Rate
B10: Risk Free Rate | F10: 0.04383 | H10: Use 10 Year Treasury
B11: Beta | F11: 1.09
B12: Market Risk Premium | F12: 0.0394
B14: Debt | F14: =275.2+1300.6 -> 1575.8
B15: % of Debt | F15: =F14/(F7+F14) -> 0.054955632
B16: Cost of Debt | F16: =(F14/F19) -> 0.054955632
B17: Tax Rate | F17: =DCF!L19 -> 0.29833566
B19: Total | F19: =F7+F14 -> 28674.04
B21: WACC | F21: =F8*F9+(F15*F16*(1-F17)) -> 0.084126282

Sheet Shares
B2: Diluted Share Count Calculation
A4: x | B4: Full Diluted Shares
B6: Current Stock Price | E6: =DCF!I4 -> 205.57
B7: Basic shares outstanding (latest filing) | E7: 115.52123
B8: In the money exercisable options | E8: =E30 -> 0
B9: Total proceeds ($mm) | E9: =SUMPRODUCT(D19:D28,E19:E28) -> 0
B10: Total shares repurchased (mm) | E10: =E9/E6 -> 0
B11: Net dilutive options | E11: =E8-E10 -> 0
B12: Dilutive impact of shares from other securities | E12: 0.849
B14: Net diluted shares outstanding | E14: =E7+E11+E12 -> 116.37023
A16: x | B16: Options outstanding
C18: Outstanding | D18: Exercise Price | E18: Diliutive Shares
B19: Tranche 1 | E19: =IF(D19<$E$6,C19) -> 0
B20: Tranche 2 | E20: =IF(D20<$E$6,C20) -> 0
B21: Tranche 3 | E21: =IF(D21<$E$6,C21) -> 0
B22: Tranche 4 | E22: =IF(D22<$E$6,C22) -> 0
B23: Tranche 5 | E23: =IF(D23<$E$6,C23) -> 0
B24: Tranche 6 | E24: =IF(D24<$E$6,C24) -> 0
B25: Tranche 7 | E25: =IF(D25<$E$6,C25) -> 0
B26: Tranche 8 | E26: =IF(D26<$E$6,C26) -> 0
B27: Tranche 9 | E27: =IF(D27<$E$6,C27) -> 0
B28: Tranche 10 | E28: =IF(D28<$E$6,C28) -> 0
B30: Total | E30: =SUM(E19:E28) -> 0

Sheet IS
A1: lululemon athletica inc. (LULU)
A2: $226.11
A5: lululemon athletica inc.
A6: LULU 550021109 B23FN39 NASDAQ Common stock
A7: Source: FactSet Fundamentals
B8: JAN '16 | C8: JAN '17 | D8: JAN '18 | E8: JAN '19 | F8: JAN '20 | G8: JAN '21 | H8: JAN '22 | I8: JAN '23 | J8: JAN '24 | K8: JAN '25 | L8: APR '25
L9: LTM
A10: Sales | B10: 2060.523 | C10: 2344.392 | D10: 2649.181 | E10: 3288.319 | F10: 3979.296 | G10: 4401.879 | H10: 6256.617 | I10: 8110.518 | J10: 9619.278 | K10: 10588.126 | L10: 10749.895
A11: Cost of Goods Sold (COGS) incl. D&A | B11: 1063.357 | C11: 1144.775 | D11: 1241.693 | E11: 1472.032 | F11: 1755.91 | G11: 1943.048 | H11: 2656.834 | I11: 3626.93 | J11: 4014.883 | K11: 4320.05 | L11: 4375.391
A12: COGS excluding D&A | B12: 989.974 | C12: 1057.078 | D12: 1133.458 | E12: 1349.548 | F12: 1594.11 | G12: 1757.788 | H12: 2432.628 | I12: 3335.139 | J12: 3635.499 | K12: 3873.526 | L12: 3910.097
A13: Depreciation & Amortization Expense | B13: 73.383 | C13: 87.697 | D13: 108.235 | E13: 122.484 | F13: 161.8 | G13: 185.26 | H13: 224.206 | I13: 291.791 | J13: 379.384 | K13: 446.524 | L13: 465.294
A14: Depreciation | B14: 72.573 | C14: 86.997 | D14: 108.235 | E14: 122.484 | F14: 161.8 | G14: 180.1 | H14: 215.424 | I14: 283.039 | J14: 374.374 | K14: 443.789 | L14: 460.929
A15: Amortization of Intangibles | B15: 0.81 | C15: 0.7 | D15: 0 | G15: 5.16 | H15: 8.782 | I15: 8.752 | J15: 5.01 | K15: 2.735 | L15: 4.365
A16: Gross Income | B16: 997.166 | C16: 1199.617 | D16: 1407.488 | E16: 1816.287 | F16: 2223.386 | G16: 2458.831 | H16: 3599.783 | I16: 4483.588 | J16: 5604.395 | K16: 6268.076 | L16: 6374.504
A17: SG&A Expense | B17: 640.048 | C17: 770.165 | D17: 911.581 | E17: 1111.844 | F17: 1332.768 | G17: 1642.999 | H17: 2216.671 | I17: 2749.912 | J17: 3396.751 | K17: 3768.299 | L17: 3826.255
A18: Other SG&A | B18: 640.048 | C18: 770.165 | D18: 911.581 | E18: 1111.844 | F18: 1332.768 | G18: 1642.999 | H18: 2216.671 | I18: 2749.912 | J18: 3396.751 | K18: 3768.299 | L18: 3826.255
A19: EBIT (Operating Income) | B19: 357.118 | C19: 429.452 | D19: 495.907 | E19: 704.443 | F19: 890.618 | G19: 815.832 | H19: 1383.112 | I19: 1733.676 | J19: 2207.644 | K19: 2499.777 | L19: 2548.249
A20: Nonoperating Income - Net | B20: 11.377 | C20: -6.723 | D20: 3.997 | E20: 33.056 | F20: 10.984 | G20: -26.689 | H20: 12.025 | I20: 18.753 | J20: 19.827 | K20: 198.223 | L20: 66.842
A21: Other Income (Expense) | B21: 11.377 | C21: -6.723 | D21: 3.997 | E21: 33.056 | F21: 10.984 | G21: -26.689 | H21: 12.025 | I21: 18.753 | J21: 19.827 | K21: 198.223 | L21: 66.842
A22: Unusual Expense - Net | D22: 39.906 | E22: 22.249 | F22: 4.209 | G22: -30.207 | H22: 61.268 | I22: 419.858 | J22: 51.736 | K22: 121.923 | L22: 44.528
A23: Impairments | I23: 407.913 | J23: 44.186
A24: Goodwill | B24: 0 | C24: 0 | D24: 0 | E24: 0 | F24: 0 | G24: 0 | H24: 0 | I24: 362.492 | J24: 0 | K24: 0 | L24: 0
A25: Other Intangibles | B25: 0 | C25: 0 | D25: 0 | E25: 0 | F25: 0 | G25: 0 | H25: 0 | I25: 40.585 | J25: 33.025 | K25: 0 | L25: 0
A26: Property,Plant & Equipment | I26: 4.836 | J26: 11.161
A27: Restructuring Expense | B27: 0 | C27: 0 | D27: 47.223 | E27: 0 | F27: 0 | G27: 29.842 | H27: 41.394 | I27: 0 | J27: 30.315 | K27: 3.5 | L27: 3.5
A28: Unrealized Valuation Gain/Loss | D28: 7.317 | E28: -22.249 | F28: -4.209 | G28: 22.949 | H28: -19.874 | I28: -11.945 | J28: 22.765 | K28: -118.423 | L28: -41.028
A29: Hedges/Derivatives | D29: 7.317 | E29: -22.249 | F29: -4.209 | G29: 22.949 | H29: -19.874 | I29: -11.945 | J29: 22.765 | K29: -118.423 | L29: -41.028
A30: Excpl Chrgs - Others | G30: -37.1
A31: Other Unusual Expense | G31: -37.1
A32: Pretax Income | B32: 368.495 | C32: 422.729 | D32: 459.998 | E32: 715.25 | F32: 897.393 | G32: 819.35 | H32: 1333.869 | I32: 1332.571 | J32: 2175.735 | K32: 2576.077 | L32: 2570.563
A33: Income Taxes | B33: 102.448 | C33: 119.348 | D33: 201.336 | E33: 231.449 | F33: 251.797 | G33: 230.437 | H33: 358.547 | I33: 477.771 | J33: 625.545 | K33: 761.461 | L33: 762.796
A34: Income Taxes - Current Domestic | B34: -15.299 | C34: 42.935 | D34: 91.297 | E34: 89.366 | F34: 57.245 | G34: 10.509 | H34: 43.309 | I34: 68.121 | J34: 183.202 | K34: 118.834
